Workbook
Name POC_Criteria: #REF!

Sheet 01_Key Requirements & Use Cases
B2: RQ # | C2: Requirements / Use Cases | D2: Minimum Acceptance Criteria / Expected outcome | E2: Requirement Type | F2: Requirement Category | G2: Weightage 1 = Low 2 = High 3 = Critical | H2: Comments
B3: RQ. 01 | C3: Backup and restore for Sharepoint data | D3: Restore granular Sharepoint data | E3: Functional | F3: Functional Capabilities | G3: 3
B4: RQ. 02 | C4: Backup and restore for Onedrive data | D4: Restore granular Onedrive data | E4: Functional | F4: Functional Capabilities | G4: 3
B5: RQ. 03 | C5: Backup and restore for Exchange Online data | D5: Restore granular Exchange data (email, calendar). | E5: Functional | F5: Functional Capabilities | G5: 3
B6: RQ. 04 | C6: Backup and restore for Teams | D6: Restore granular teams chats | E6: Functional | F6: Functional Capabilities | G6: 3
B7: RQ. 05 | C7: Backup and restore for Entra ID | D7: Restore granular Entra ID data | E7: Functional | F7: Functional Capabilities | G7: 3
B8: RQ. 06 | C8: Supports backup across different CSP backup storages for secondary backup copy. | D8: Able to store backup in seperate location to the primary storage and also have a capability to store backup in different CSPs. | E8: Functional | F8: Resillience | G8: 2
B9: RQ. 07 | C9: Support long term retention up to 10 years. | D9: Set retention to 7 to 10 years or above. | E9: Non-Functional | F9: Regulatory Compliance | G9: 3
B10: RQ. 08 | C10: Support Okta or Entra ID for role-based access control. | D10: Integrated with AIA Identity management | E10: Non-Functional | F10: Access Controls | G10: 3
B11: RQ. 09 | C11: Support 15-30 mins user timeout on admin console. | D11: Prevent unauthorized access to sensitive data when a user leaves a session unattended. | E11: Non-Functional | F11: Information Security | G11: 2
B12: RQ. 10 | C12: Support storage account tiering (hot, cold, archive). | D12: Storage Optimization | E12: Non-Functional | F12: Cloud Readiness | G12: 2
B13: RQ. 11 | C13: Support data deduplication | D13: Storage Optimization | E13: Non-Functional | F13: Operations | G13: 2
B14: RQ. 12 | C14: SaaS model | D14: Using a subscription model | E14: Optional | F14: Architecture | G14: 1
... B19: RQ. 17 | C19: Support backup of Retention and Litigation Hold Items | D19: Backup of data in the hold library | E19: Functional | F19: Functional Capabilities | G19: 3
B20: RQ. 18 | C20: Backup of data in the Microsoft Archive storage | D20: Capability to backup archived data | E20: Functional | F20: Functional Capabilities | G20: 3 | H20: AIA already has data archived in MS;
B21: RQ. 19 | C21: Support 256-bit encryption | D21: Support encryption at rest and transit | E21: Non-Functional | F21: Information Security | G21: 2
B22: RQ. 20 | C22: Support MFA | D22: Two Factor Authentication | E22: Non-Functional | F22: Information Security | G22: 2
B23: RQ. 21 | C23: Unlimited Storage | D23: Keep the data backup of unlicensed users once backup | E23: Functional | F23: Cost & Contract | G23: 2
B24: RQ. 22 | C24: Dynamic Disaster Recovery | D24: Features lightning-fast bulk restore, advanced search, and compare capabilities for rapid recovery at scale. | E24: Functional | F24: Functional Capabilities | G24: 3
B25: RQ. 23 | C25: Monitoring and Reporting | D25: Reports to monitor backup status, performance and compliance | E25: Non-Functional | F25: Log, Monitor & Alerts | G25: 3
B26: RQ. 24 | C26: Logging | D26: Audit and other logs for troubleshooting | E26: Non-Functional | F26: Log, Monitor & Alerts | G26: 3
B27: RQ. 25 | C27: Multi-Tenant Support | D27: Capable of backing up multiple Entra ID tenants within a single deployment. | E27: Functional | F27: Integration | G27: 2
B28: RQ. 26 | C28: Disaster Recovey across Regions | D28: Geo replicated data copy | E28: Non-Functional | F28: Resillience | G28: 3
B29: RQ. 27 | C29: Support of Local data residency | D29: Support data residency for Business units such as KR, TW, AU, CN | E29: Non-Functional | F29: Regulatory Compliance | G29: 3
B30: RQ. 28 | C30: Operational support | D30: SLA and Support location and Language | E30: Non-Functional | F30: Delivery & Transition | G30: 3
B31: RQ. 29 | C31: Backup and restore of PowerBI | D31: Not part of core requirements; good to have. | E31: Functional | F31: Functional Capabilities | G31: 1
B32: RQ. 30 | C32: Backup and restore of MS Dynamics SaaS | D32: Not part of core requirements; good to have. | E32: Functional | F32: Functional Capabilities | G32: 1
B33: RQ. 31 | C33: Retention still enabled for inactive users (left company) | D33: Active retention for inactive/resigned users. | E33: Non-Functional | F33: Regulatory Compliance | G33: 3
B34: RQ. 32
B35: RQ. 33
B36: RQ. 34
B37: RQ. 35
B38: RQ. 36
B39: RQ. 37
B40: RQ. 38
B41: RQ. 39
B42: RQ. 40
B43: RQ. 41
B44: RQ. 42
B45: RQ. 43
...

Sheet 02_M365 Backup Assessment
A1: Microsoft 365 Backup - Requirements Assessment Summary
A2: Assessment of Microsoft 365 Backup (first-party) against the 31 stated requirements. Scoring: 3 = full capability, 2 = partial, 1 = limited / achieved by an adjacent Microsoft capability, 0 = not supported.
A4: RQ # | B4: Requirement | C4: Weight | D4: Compliance | E4: Score (0-3) | F4: Assessment / Alternative
A5: RQ. 01 | B5: Backup and restore for Sharepoint data | C5: 3 | D5: In-Full | E5: 3 | F5: Fully supported. Site-level backup of all or selected SharePoint sites; restore to same or new URL. Full-site rollback to a prior point in time, plus granular folder/file and file-version restore. RPO: 10-minute restore points for the trailing 2 weeks, then weekly restore points from 2 weeks out to the full 2-year retention period. Note: a small set of legacy site templates is unsupported (Review Center, Policy Center, Tenant admin site, MySite Host, SharePoint Embedded containers).
A6: RQ. 02 | B6: Backup and restore for Onedrive data | C6: 3 | D6: In-Full | E6: 3 | F6: Fully supported. Backup granularity = OneDrive account; restore to same or new URL, full-account rollback plus granular file/folder and version restore. Same restore point model as SharePoint - 10-minute restore points for the trailing 2 weeks, then weekly restore points out to the full 2-year retention period.
A7: RQ. 03 | B7: Backup and restore for Exchange Online data | C7: 3 | D7: In-Full | E7: 3 | F7: Fully supported. Mailbox-level backup with full mailbox or granular item restore via search - mail, contacts, calendar and tasks. 10-minute RPO across the full 2-year retention period; all deletions are captured. Restore lands in the same or a new folder in the user's mailbox and only re-instates modified/deleted items. Caveat: only 'versioned' events are recoverable (edits/deletions). Some changes are not versioned, e.g. edits to items in Drafts, flag changes, sensitivity/DNF changes.
A8: RQ. 04 | B8: Backup and restore for Teams | C8: 3 | D8: Non-Compliant | E8: 0 | F8: NOT supported. Microsoft 365 Backup covers SharePoint, OneDrive and Exchange Online only - Teams chat and channel messages are not protection units. Partial mitigation: Teams channel files live in SharePoint and chat files in OneDrive, so file content IS protected; and Teams chat/channel messages are compliance-retained in the substrate (backed by Exchange). Alternatives: (a) Purview retention policies for Teams chat/channel messages + eDiscovery export for recovery; (b) an ISV built on the Microsoft 365 Backup Storage platform (e.g. Veeam, Commvault, AvePoint) which adds Teams message backup on top of the same fast Microsoft backup fabric.
A9: RQ. 05 | B9: Backup and restore for Entra ID | C9: 3 | D9: Non-Compliant | E9: 0 | F9: NOT supported. Entra ID objects (users, groups, roles, CA policies, app registrations) are out of scope for Microsoft 365 Backup. Alternatives: (a) native Entra ID soft-delete / recycle bin - 30 days for users, groups and applications; (b) Microsoft Entra ID Governance + Entra Recovery/restore APIs and Graph-based config-as-code (e.g. exporting Conditional Access and role assignments to a Git repo); (c) a third-party Entra ID backup product (Veeam, Commvault, Quest On Demand Recovery) if item-level directory rollback is a hard requirement.
A10: RQ. 06 | B10: Supports backup across different CSP backup storages for secondary backup copy. | C10: 2 | D10: Non-Compliant | E10: 0 | F10: NOT supported. By design, backup data never leaves the Microsoft 365 data trust boundary - only billing metadata (tenantID/siteID) goes to Azure. There is no capability to write a secondary copy to another CSP's storage or to customer-owned object storage. Alternative: run an ISV backup product (Veeam/Commvault/AvePoint/Rubrik) in parallel that writes to Azure Blob, AWS S3 or on-prem object storage for the second copy. Trade-off to make explicit with the customer: an out-of-boundary copy delivers CSP diversity but loses the in-boundary restore speed (Microsoft 365 Backup restores at up to ~2 TB/hr and 250 protection units/hr because it never moves data across the network).
A11: RQ. 07 | B11: Support long term retention up to 10 years. | C11: 3 | D11: Non-Compliant | E11: 0 | F11: NOT supported at 7-10 years. Maximum retention is 2 years for SharePoint, OneDrive and Exchange. Important framing for the customer: backup and long-term compliance retention are different problems. Alternatives for the 7-10 year requirement: (a) Microsoft Purview retention policies and retention labels - supports multi-year to permanent retention with disposition review, and is the supported control for regulatory retention; (b) Exchange Online Archiving with auto-expanding archive; (c) an ISV backup product if the requirement is genuinely 10-year restorable *backup* rather than compliance retention. Recommended position: Microsoft 365 Backup for operational/ransomware recovery (0-2 years) + Purview for 7-10 year regulatory retention.
A12: RQ. 08 | B12: Support Okta or Entra ID for role-based access control. | C12: 3 | D12: Partially | E12: 2 | F12: Supported via Entra ID role-based access control. Dedicated least-privilege role 'Microsoft 365 Backup Administrator' controls the whole tool; Global Administrator covers all three workloads; SharePoint Administrator covers SharePoint/OneDrive; Exchange Administrator covers Exchange. Okta is not natively integrated - it is supported indirectly where Okta is federated to Entra ID as the identity provider, but authorisation still resolves to Entra ID roles. If AIA's IAM standard requires Okta-native RBAC group mapping, that must be achieved through Okta-to-Entra provisioning/federation.
A13: RQ. 09 | B13: Support 15-30 mins user timeout on admin console. | C13: 2 | D13: Partially | E13: 2 | F13: Partially supported - not a setting inside the Backup tool. The console is the Microsoft 365 admin center, so session control is enforced at the identity layer: Entra ID Conditional Access sign-in frequency (can be set to a specific number of hours/minutes) and the Microsoft 365 idle session sign-out policy. Recommend validating that the exact 15-30 minute idle target can be met with the customer's Conditional Access configuration during PoC.
A14: RQ. 10 | B14: Support storage account tiering (hot, cold, archive). | C14: 2 | D14: Partially | E14: 1 | F14: Partially - the intent (storage cost optimisation) is met, but not through customer-managed tiers. Microsoft 365 Backup has no customer-managed storage tiers - it is a flat consumption price of USD 0.15 per GB per month of protected data, with restores free. There is no hot/cool/archive tier to tune. Related but separate product: Microsoft 365 Archive lets you move cold SharePoint sites to a lower-cost tier while keeping them in place. Note the requirement's intent (storage cost optimisation) is partly met by the fact that Microsoft manages the storage efficiency and restores are not charged.
A15: RQ. 11 | B15: Support data deduplication | C15: 2 | D15: Partially | E15: 1 | F15: No customer-visible or customer-configurable deduplication. Storage efficiency is handled internally - backups are change-based/incremental and stored on append-only blob storage built on the SharePoint/OneDrive and Exchange infrastructure, so unchanged content is not re-stored. However you cannot report on, or tune, a dedup ratio, and billing is on the volume of protected data rather than on stored backup data.
A16: RQ. 12 | B16: SaaS model | C16: 1 | D16: In-Full | E16: 3 | F16: Fully supported as SaaS - first-party Microsoft service, no infrastructure, agents or connectors to deploy or patch. One nuance vs. the requirement wording: commercial model is pay-as-you-go consumption billed through an Azure subscription (USD 0.15/GB/month), not a per-user subscription licence. Departmental billing across multiple Azure subscriptions is supported if AIA needs cost split by business unit.
... A35: RQ. 31 | B35: Retention still enabled for inactive users (left company) | C35: 3 | D35: Partially | E35: 2 | F35: Partially supported. Backups of a departed user's OneDrive and mailbox continue to be retained for 2 years from the date each backup was created, even after the user is removed from the policy or deleted from Entra ID, and hard-deleted mailboxes are preserved as inactive mailboxes while the policy remains in effect. Recovery path is documented (Restore a user within 30 days of soft-delete, or Recover an inactive mailbox - note the 'Restore an inactive mailbox' path does NOT preserve backup data). Gap: 2-year ceiling, which will not satisfy a 7-10 year leaver-retention obligation - pair with Purview retention policies and inactive mailboxes for the regulatory tail.
A38: Coverage Summary
A39: Measure | B39: Count | C39: % of total
A40: Requirements assessed | B40: 31
A41: Met in full (In-Full) | B41: 15 | C41: 48%
A42: Met in part (Partially) | B42: 10 | C42: 32%
A43: Addressed in full or in part | B43: 25 | C43: 81%
A44: Not supported (Non-Compliant) | B44: 6 | C44: 19%
A45: Weighted capability score (0-3 scored against requirement weighting) | C45: 69%
A46: Critical (weight 3) requirements addressed | B46: 15 of 18 | C46: 83%
A47: Critical requirements met in full | B47: 10 of 18 | C47: 56%
A48: Addressed, excluding "good to have" (RQ.29, RQ.30) | B48: 25 of 29 | C48: 86%
A50: Non-compliant requirements: RQ. 04, RQ. 05, RQ. 06, RQ. 07, RQ. 29, RQ. 30
A51: Of these, critical (weight 3): RQ. 04, RQ. 05, RQ. 07

Sheet 03_Product(s) Evaluation
B1: Initial Product Review (all products, shortlist 3-5).
G2: M365 Backup | I2: Veeam M365 | K2: Commvault
B3: RQ # | C3: Requirements / Use Cases | D3: Minimum Acceptance Criteria / Expected outcome | E3: Requirement Type | F3: Requirement Category | G3: Capability Score | H3: Comments | I3: Capability Score | J3: Comments | K3: Capability Score | L3: Comments | M3: Capability Score | N3: Comments | O3: Capability Score | P3: Comments | Q3: Capability Score | R3: Comments
B4: =IFERROR('01_Key Requirements & Use Cases'!$B3,"") | C4: =IFERROR('01_Key Requirements & Use Cases'!$C3,"") | D4: =IFERROR('01_Key Requirements & Use Cases'!$D3,"") | E4: =IFERROR('01_Key Requirements & Use Cases'!$E3,"") | F4: =IFERROR('01_Key Requirements & Use Cases'!$F3,"") | G4: 3 | H4: Fully supported. Site-level backup of all or selected SharePoint sites; restore to same or new URL. Full-site rollback to a prior point in time, plus granular folder/file and file-version restore. RPO: 10-minute restore points for the trailing 2 weeks, then weekly restore points from 2 weeks out to the full 2-year retention period. Note: a small set of legacy site templates is unsupported (Review Center, Policy Center, Tenant admin site, MySite Host, SharePoint Embedded containers).
B5: =IFERROR('01_Key Requirements & Use Cases'!$B4,"") | C5: =IFERROR('01_Key Requirements & Use Cases'!$C4,"") | D5: =IFERROR('01_Key Requirements & Use Cases'!$D4,"") | E5: =IFERROR('01_Key Requirements & Use Cases'!$E4,"") | F5: =IFERROR('01_Key Requirements & Use Cases'!$F4,"") | G5: 3 | H5: Fully supported. Backup granularity = OneDrive account; restore to same or new URL, full-account rollback plus granular file/folder and version restore. Same restore point model as SharePoint - 10-minute restore points for the trailing 2 weeks, then weekly restore points out to the full 2-year retention period.
B6: =IFERROR('01_Key Requirements & Use Cases'!$B5,"") | C6: =IFERROR('01_Key Requirements & Use Cases'!$C5,"") | D6: =IFERROR('01_Key Requirements & Use Cases'!$D5,"") | E6: =IFERROR('01_Key Requirements & Use Cases'!$E5,"") | F6: =IFERROR('01_Key Requirements & Use Cases'!$F5,"") | G6: 3 | H6: Fully supported. Mailbox-level backup with full mailbox or granular item restore via search - mail, contacts, calendar and tasks. 10-minute RPO across the full 2-year retention period; all deletions are captured. Restore lands in the same or a new folder in the user's mailbox and only re-instates modified/deleted items. Caveat: only 'versioned' events are recoverable (edits/deletions). Some changes are not versioned, e.g. edits to items in Drafts, flag changes, sensitivity/DNF changes.
B7: =IFERROR('01_Key Requirements & Use Cases'!$B6,"") | C7: =IFERROR('01_Key Requirements & Use Cases'!$C6,"") | D7: =IFERROR('01_Key Requirements & Use Cases'!$D6,"") | E7: =IFERROR('01_Key Requirements & Use Cases'!$E6,"") | F7: =IFERROR('01_Key Requirements & Use Cases'!$F6,"") | G7: 0 | H7: NOT supported. Microsoft 365 Backup covers SharePoint, OneDrive and Exchange Online only - Teams chat and channel messages are not protection units. Partial mitigation: Teams channel files live in SharePoint and chat files in OneDrive, so file content IS protected; and Teams chat/channel messages are compliance-retained in the substrate (backed by Exchange). Alternatives: (a) Purview retention policies for Teams chat/channel messages + eDiscovery export for recovery; (b) an ISV built on the Microsoft 365 Backup Storage platform (e.g. Veeam, Commvault, AvePoint) which adds Teams message backup on top of the same fast Microsoft backup fabric.
B8: =IFERROR('01_Key Requirements & Use Cases'!$B7,"") | C8: =IFERROR('01_Key Requirements & Use Cases'!$C7,"") | D8: =IFERROR('01_Key Requirements & Use Cases'!$D7,"") | E8: =IFERROR('01_Key Requirements & Use Cases'!$E7,"") | F8: =IFERROR('01_Key Requirements & Use Cases'!$F7,"") | G8: 0 | H8: NOT supported. Entra ID objects (users, groups, roles, CA policies, app registrations) are out of scope for Microsoft 365 Backup. Alternatives: (a) native Entra ID soft-delete / recycle bin - 30 days for users, groups and applications; (b) Microsoft Entra ID Governance + Entra Recovery/restore APIs and Graph-based config-as-code (e.g. exporting Conditional Access and role assignments to a Git repo); (c) a third-party Entra ID backup product (Veeam, Commvault, Quest On Demand Recovery) if item-level directory rollback is a hard requirement.
B9: =IFERROR('01_Key Requirements & Use Cases'!$B8,"") | C9: =IFERROR('01_Key Requirements & Use Cases'!$C8,"") | D9: =IFERROR('01_Key Requirements & Use Cases'!$D8,"") | E9: =IFERROR('01_Key Requirements & Use Cases'!$E8,"") | F9: =IFERROR('01_Key Requirements & Use Cases'!$F8,"") | G9: 0 | H9: NOT supported. By design, backup data never leaves the Microsoft 365 data trust boundary - only billing metadata (tenantID/siteID) goes to Azure. There is no capability to write a secondary copy to another CSP's storage or to customer-owned object storage. Alternative: run an ISV backup product (Veeam/Commvault/AvePoint/Rubrik) in parallel that writes to Azure Blob, AWS S3 or on-prem object storage for the second copy. Trade-off to make explicit with the customer: an out-of-boundary copy delivers CSP diversity but loses the in-boundary restore speed (Microsoft 365 Backup restores at up to ~2 TB/hr and 250 protection units/hr because it never moves data across the network).
B10: =IFERROR('01_Key Requirements & Use Cases'!$B9,"") | C10: =IFERROR('01_Key Requirements & Use Cases'!$C9,"") | D10: =IFERROR('01_Key Requirements & Use Cases'!$D9,"") | E10: =IFERROR('01_Key Requirements & Use Cases'!$E9,"") | F10: =IFERROR('01_Key Requirements & Use Cases'!$F9,"") | G10: 0 | H10: NOT supported at 7-10 years. Maximum retention is 2 years for SharePoint, OneDrive and Exchange. Important framing for the customer: backup and long-term compliance retention are different problems. Alternatives for the 7-10 year requirement: (a) Microsoft Purview retention policies and retention labels - supports multi-year to permanent retention with disposition review, and is the supported control for regulatory retention; (b) Exchange Online Archiving with auto-expanding archive; (c) an ISV backup product if the requirement is genuinely 10-year restorable *backup* rather than compliance retention. Recommended position: Microsoft 365 Backup for operational/ransomware recovery (0-2 years) + Purview for 7-10 year regulatory retention.
B11: =IFERROR('01_Key Requirements & Use Cases'!$B10,"") | C11: =IFERROR('01_Key Requirements & Use Cases'!$C10,"") | D11: =IFERROR('01_Key Requirements & Use Cases'!$D10,"") | E11: =IFERROR('01_Key Requirements & Use Cases'!$E10,"") | F11: =IFERROR('01_Key Requirements & Use Cases'!$F10,"") | G11: 2 | H11: Supported via Entra ID role-based access control. Dedicated least-privilege role 'Microsoft 365 Backup Administrator' controls the whole tool; Global Administrator covers all three workloads; SharePoint Administrator covers SharePoint/OneDrive; Exchange Administrator covers Exchange. Okta is not natively integrated - it is supported indirectly where Okta is federated to Entra ID as the identity provider, but authorisation still resolves to Entra ID roles. If AIA's IAM standard requires Okta-native RBAC group mapping, that must be achieved through Okta-to-Entra provisioning/federation.
B12: =IFERROR('01_Key Requirements & Use Cases'!$B11,"") | C12: =IFERROR('01_Key Requirements & Use Cases'!$C11,"") | D12: =IFERROR('01_Key Requirements & Use Cases'!$D11,"") | E12: =IFERROR('01_Key Requirements & Use Cases'!$E11,"") | F12: =IFERROR('01_Key Requirements & Use Cases'!$F11,"") | G12: 2 | H12: Partially supported - not a setting inside the Backup tool. The console is the Microsoft 365 admin center, so session control is enforced at the identity layer: Entra ID Conditional Access sign-in frequency (can be set to a specific number of hours/minutes) and the Microsoft 365 idle session sign-out policy. Recommend validating that the exact 15-30 minute idle target can be met with the customer's Conditional Access configuration during PoC.
B13: =IFERROR('01_Key Requirements & Use Cases'!$B12,"") | C13: =IFERROR('01_Key Requirements & Use Cases'!$C12,"") | D13: =IFERROR('01_Key Requirements & Use Cases'!$D12,"") | E13: =IFERROR('01_Key Requirements & Use Cases'!$E12,"") | F13: =IFERROR('01_Key Requirements & Use Cases'!$F12,"") | G13: 1 | H13: Partially - the intent (storage cost optimisation) is met, but not through customer-managed tiers. Microsoft 365 Backup has no customer-managed storage tiers - it is a flat consumption price of USD 0.15 per GB per month of protected data, with restores free. There is no hot/cool/archive tier to tune. Related but separate product: Microsoft 365 Archive lets you move cold SharePoint sites to a lower-cost tier while keeping them in place. Note the requirement's intent (storage cost optimisation) is partly met by the fact that Microsoft manages the storage efficiency and restores are not charged.
B14: =IFERROR('01_Key Requirements & Use Cases'!$B13,"") | C14: =IFERROR('01_Key Requirements & Use Cases'!$C13,"") | D14: =IFERROR('01_Key Requirements & Use Cases'!$D13,"") | E14: =IFERROR('01_Key Requirements & Use Cases'!$E13,"") | F14: =IFERROR('01_Key Requirements & Use Cases'!$F13,"") | G14: 1 | H14: No customer-visible or customer-configurable deduplication. Storage efficiency is handled internally - backups are change-based/incremental and stored on append-only blob storage built on the SharePoint/OneDrive and Exchange infrastructure, so unchanged content is not re-stored. However you cannot report on, or tune, a dedup ratio, and billing is on the volume of protected data rather than on stored backup data.
B15: =IFERROR('01_Key Requirements & Use Cases'!$B14,"") | C15: =IFERROR('01_Key Requirements & Use Cases'!$C14,"") | D15: =IFERROR('01_Key Requirements & Use Cases'!$D14,"") | E15: =IFERROR('01_Key Requirements & Use Cases'!$E14,"") | F15: =IFERROR('01_Key Requirements & Use Cases'!$F14,"") | G15: 3 | H15: Fully supported as SaaS - first-party Microsoft service, no infrastructure, agents or connectors to deploy or patch. One nuance vs. the requirement wording: commercial model is pay-as-you-go consumption billed through an Azure subscription (USD 0.15/GB/month), not a per-user subscription licence. Departmental billing across multiple Azure subscriptions is supported if AIA needs cost split by business unit.
... B34: =IFERROR('01_Key Requirements & Use Cases'!$B33,"") | C34: =IFERROR('01_Key Requirements & Use Cases'!$C33,"") | D34: =IFERROR('01_Key Requirements & Use Cases'!$D33,"") | E34: =IFERROR('01_Key Requirements & Use Cases'!$E33,"") | F34: =IFERROR('01_Key Requirements & Use Cases'!$F33,"") | G34: 2 | H34: Partially supported. Backups of a departed user's OneDrive and mailbox continue to be retained for 2 years from the date each backup was created, even after the user is removed from the policy or deleted from Entra ID, and hard-deleted mailboxes are preserved as inactive mailboxes while the policy remains in effect. Recovery path is documented (Restore a user within 30 days of soft-delete, or Recover an inactive mailbox - note the 'Restore an inactive mailbox' path does NOT preserve backup data). Gap: 2-year ceiling, which will not satisfy a 7-10 year leaver-retention obligation - pair with Purview retention policies and inactive mailboxes for the regulatory tail.
B35: =IFERROR('01_Key Requirements & Use Cases'!$B34,"") | C35: =IFERROR('01_Key Requirements & Use Cases'!$C34,"") | D35: =IFERROR('01_Key Requirements & Use Cases'!$D34,"") | E35: =IFERROR('01_Key Requirements & Use Cases'!$E34,"") | F35: =IFERROR('01_Key Requirements & Use Cases'!$F34,"")
B36: =IFERROR('01_Key Requirements & Use Cases'!$B35,"") | C36: =IFERROR('01_Key Requirements & Use Cases'!$C35,"") | D36: =IFERROR('01_Key Requirements & Use Cases'!$D35,"") | E36: =IFERROR('01_Key Requirements & Use Cases'!$E35,"") | F36: =IFERROR('01_Key Requirements & Use Cases'!$F35,"")
B37: =IFERROR('01_Key Requirements & Use Cases'!$B36,"") | C37: =IFERROR('01_Key Requirements & Use Cases'!$C36,"") | D37: =IFERROR('01_Key Requirements & Use Cases'!$D36,"") | E37: =IFERROR('01_Key Requirements & Use Cases'!$E36,"") | F37: =IFERROR('01_Key Requirements & Use Cases'!$F36,"")
B38: =IFERROR('01_Key Requirements & Use Cases'!$B37,"") | C38: =IFERROR('01_Key Requirements & Use Cases'!$C37,"") | D38: =IFERROR('01_Key Requirements & Use Cases'!$D37,"") | E38: =IFERROR('01_Key Requirements & Use Cases'!$E37,"") | F38: =IFERROR('01_Key Requirements & Use Cases'!$F37,"")
B39: =IFERROR('01_Key Requirements & Use Cases'!$B38,"") | C39: =IFERROR('01_Key Requirements & Use Cases'!$C38,"") | D39: =IFERROR('01_Key Requirements & Use Cases'!$D38,"") | E39: =IFERROR('01_Key Requirements & Use Cases'!$E38,"") | F39: =IFERROR('01_Key Requirements & Use Cases'!$F38,"")
B40: =IFERROR('01_Key Requirements & Use Cases'!$B39,"") | C40: =IFERROR('01_Key Requirements & Use Cases'!$C39,"") | D40: =IFERROR('01_Key Requirements & Use Cases'!$D39,"") | E40: =IFERROR('01_Key Requirements & Use Cases'!$E39,"") | F40: =IFERROR('01_Key Requirements & Use Cases'!$F39,"")
B41: =IFERROR('01_Key Requirements & Use Cases'!$B40,"") | C41: =IFERROR('01_Key Requirements & Use Cases'!$C40,"") | D41: =IFERROR('01_Key Requirements & Use Cases'!$D40,"") | E41: =IFERROR('01_Key Requirements & Use Cases'!$E40,"") | F41: =IFERROR('01_Key Requirements & Use Cases'!$F40,"")
B42: =IFERROR('01_Key Requirements & Use Cases'!$B41,"") | C42: =IFERROR('01_Key Requirements & Use Cases'!$C41,"") | D42: =IFERROR('01_Key Requirements & Use Cases'!$D41,"") | E42: =IFERROR('01_Key Requirements & Use Cases'!$E41,"") | F42: =IFERROR('01_Key Requirements & Use Cases'!$F41,"")
B43: =IFERROR('01_Key Requirements & Use Cases'!$B42,"") | C43: =IFERROR('01_Key Requirements & Use Cases'!$C42,"") | D43: =IFERROR('01_Key Requirements & Use Cases'!$D42,"") | E43: =IFERROR('01_Key Requirements & Use Cases'!$E42,"") | F43: =IFERROR('01_Key Requirements & Use Cases'!$F42,"")
B44: =IFERROR('01_Key Requirements & Use Cases'!$B43,"") | C44: =IFERROR('01_Key Requirements & Use Cases'!$C43,"") | D44: =IFERROR('01_Key Requirements & Use Cases'!$D43,"") | E44: =IFERROR('01_Key Requirements & Use Cases'!$E43,"") | F44: =IFERROR('01_Key Requirements & Use Cases'!$F43,"")
B45: =IFERROR('01_Key Requirements & Use Cases'!$B44,"") | C45: =IFERROR('01_Key Requirements & Use Cases'!$C44,"") | D45: =IFERROR('01_Key Requirements & Use Cases'!$D44,"") | E45: =IFERROR('01_Key Requirements & Use Cases'!$E44,"") | F45: =IFERROR('01_Key Requirements & Use Cases'!$F44,"")
B46: =IFERROR('01_Key Requirements & Use Cases'!$B45,"") | C46: =IFERROR('01_Key Requirements & Use Cases'!$C45,"") | D46: =IFERROR('01_Key Requirements & Use Cases'!$D45,"") | E46: =IFERROR('01_Key Requirements & Use Cases'!$E45,"") | F46: =IFERROR('01_Key Requirements & Use Cases'!$F45,"")
... B73: =IFERROR('01_Key Requirements & Use Cases'!$B72,"") | C73: =IFERROR('01_Key Requirements & Use Cases'!$C72,"") | D73: =IFERROR('01_Key Requirements & Use Cases'!$D72,"") | E73: =IFERROR('01_Key Requirements & Use Cases'!$E72,"") | F73: =IFERROR('01_Key Requirements & Use Cases'!$F72,"")
B74: =IFERROR('01_Key Requirements & Use Cases'!$B73,"") | C74: =IFERROR('01_Key Requirements & Use Cases'!$C73,"") | D74: =IFERROR('01_Key Requirements & Use Cases'!$D61,"") | E74: =IFERROR('01_Key Requirements & Use Cases'!$E73,"") | F74: =IFERROR('01_Key Requirements & Use Cases'!$F73,"")
B75: =IFERROR('01_Key Requirements & Use Cases'!$B74,"") | C75: =IFERROR('01_Key Requirements & Use Cases'!$C74,"") | D75: =IFERROR('01_Key Requirements & Use Cases'!$D62,"") | E75: =IFERROR('01_Key Requirements & Use Cases'!$E74,"") | F75: =IFERROR('01_Key Requirements & Use Cases'!$F74,"")
B76: =IFERROR('01_Key Requirements & Use Cases'!$B75,"") | C76: =IFERROR('01_Key Requirements & Use Cases'!$C75,"") | D76: =IFERROR('01_Key Requirements & Use Cases'!$D63,"") | E76: =IFERROR('01_Key Requirements & Use Cases'!$E75,"") | F76: =IFERROR('01_Key Requirements & Use Cases'!$F75,"")
B77: =IFERROR('01_Key Requirements & Use Cases'!$B76,"") | C77: =IFERROR('01_Key Requirements & Use Cases'!$C76,"") | D77: =IFERROR('01_Key Requirements & Use Cases'!$D64,"") | E77: =IFERROR('01_Key Requirements & Use Cases'!$E76,"") | F77: =IFERROR('01_Key Requirements & Use Cases'!$F76,"")
B78: =IFERROR('01_Key Requirements & Use Cases'!$B77,"") | C78: =IFERROR('01_Key Requirements & Use Cases'!$C77,"") | D78: =IFERROR('01_Key Requirements & Use Cases'!$D65,"") | E78: =IFERROR('01_Key Requirements & Use Cases'!$E77,"") | F78: =IFERROR('01_Key Requirements & Use Cases'!$F77,"")
B79: =IFERROR('01_Key Requirements & Use Cases'!$B78,"") | C79: =IFERROR('01_Key Requirements & Use Cases'!$C78,"") | D79: =IFERROR('01_Key Requirements & Use Cases'!$D66,"") | E79: =IFERROR('01_Key Requirements & Use Cases'!$E78,"") | F79: =IFERROR('01_Key Requirements & Use Cases'!$F78,"")
B80: =IFERROR('01_Key Requirements & Use Cases'!$B79,"") | C80: =IFERROR('01_Key Requirements & Use Cases'!$C79,"") | D80: =IFERROR('01_Key Requirements & Use Cases'!$D67,"") | E80: =IFERROR('01_Key Requirements & Use Cases'!$E79,"") | F80: =IFERROR('01_Key Requirements & Use Cases'!$F79,"")
B81: =IFERROR('01_Key Requirements & Use Cases'!$B80,"") | C81: =IFERROR('01_Key Requirements & Use Cases'!$C80,"") | D81: =IFERROR('01_Key Requirements & Use Cases'!$D68,"") | E81: =IFERROR('01_Key Requirements & Use Cases'!$E80,"") | F81: =IFERROR('01_Key Requirements & Use Cases'!$F80,"")
B82: =IFERROR('01_Key Requirements & Use Cases'!$B81,"") | C82: =IFERROR('01_Key Requirements & Use Cases'!$C81,"") | D82: =IFERROR('01_Key Requirements & Use Cases'!$D69,"") | E82: =IFERROR('01_Key Requirements & Use Cases'!$E81,"") | F82: =IFERROR('01_Key Requirements & Use Cases'!$F81,"")
B83: =IFERROR('01_Key Requirements & Use Cases'!$B82,"") | C83: =IFERROR('01_Key Requirements & Use Cases'!$C82,"") | D83: =IFERROR('01_Key Requirements & Use Cases'!$D70,"") | E83: =IFERROR('01_Key Requirements & Use Cases'!$E82,"") | F83: =IFERROR('01_Key Requirements & Use Cases'!$F82,"")
B84: =IFERROR('01_Key Requirements & Use Cases'!$B83,"") | C84: =IFERROR('01_Key Requirements & Use Cases'!$C83,"") | D84: =IFERROR('01_Key Requirements & Use Cases'!$D71,"") | E84: =IFERROR('01_Key Requirements & Use Cases'!$E71,"") | F84: =IFERROR('01_Key Requirements & Use Cases'!$F71,"")
...

Sheet 05_PoC Scoring
G2: Option 1 - "Commvault" | Q2: Option 2 - "Veeam" | AA2: Option 3 - "Cohesity"
B3: Test ID | C3: UAT Description | D3: Baseline / Expected Results / Acceptance Criteria | E3: Category (Requirement) | F3: Weightage 1 = Low 2 = High 3 = Critical | G3: GE&D | H3: GTO | I3: BCM | J3: GIS | K3: HK | L3: SG | M3: Avg. Score | N3: Total Score | O3: Actual / Observed Results | P3: Comments / Remarks | Q3: GE&D | R3: GTO | S3: BCM | T3: GIS | U3: HK | V3: SG | W3: Avg. Score | X3: Total Score | Y3: Actual / Observed Results | Z3: Comments / Remarks | AA3: GE&D | AB3: GTO | AC3: BCM | AD3: GIS | AE3: HK | AF3: SG | AG3: Avg. Score | AH3: Total Score | AI3: Actual / Observed Results | AJ3: Comments / Remarks
B4: T. 01 | C4: Windows 2012 backup / restore | D4: Backup and restore success | E4: Functional | F4: 1 | G4: 3 | K4: 3 | L4: 3 | M4: =IFERROR(AVERAGE($G4,$H4,$I4,$J4,$K4,$L4),"") | N4: =IFERROR($F4*$M4,"") | O4: AW:Tested in POC with success | Q4: 3 | U4: 3 | V4: 3 | W4: =IFERROR(AVERAGE(Q4:V4),"") | X4: =IFERROR($F4*$W4,"") | AG4: =IFERROR(AVERAGE(AA4:AF4),"") | AH4: =IFERROR($F4*AG4,"")
B5: T. 02 | C5: Windows 2016 backup / restore | D5: Backup and restore success | E5: Functional | F5: 1 | G5: 3 | K5: 3 | L5: 3 | M5: =IFERROR(AVERAGE($G5,$H5,$I5,$J5,$K5,$L5),"") | N5: =IFERROR($F5*$M5,"") | O5: AW:Tested in POC with success | Q5: 3 | U5: 3 | V5: 3 | W5: =IFERROR(AVERAGE(Q5:V5),"") | X5: =IFERROR($F5*$W5,"") | AG5: =IFERROR(AVERAGE(AA5:AF5),"") | AH5: =IFERROR($F5*AG5,"")
B6: T. 03 | C6: Windows 2019 backup / restore | D6: Backup and restore success | E6: Functional | F6: 1 | G6: 3 | K6: 3 | L6: 3 | M6: =IFERROR(AVERAGE($G6,$H6,$I6,$J6,$K6,$L6),"") | N6: =IFERROR($F6*$M6,"") | O6: AW:Tested in POC with success | Q6: 3 | U6: 3 | V6: 3 | W6: =IFERROR(AVERAGE(Q6:V6),"") | X6: =IFERROR($F6*$W6,"") | AG6: =IFERROR(AVERAGE(AA6:AF6),"") | AH6: =IFERROR($F6*AG6,"")
B7: T. 04 | C7: RHEL 7.8 backup / restore | D7: Backup and restore success | E7: Functional | F7: 1 | G7: 3 | K7: 3 | L7: 3 | M7: =IFERROR(AVERAGE($G7,$H7,$I7,$J7,$K7,$L7),"") | N7: =IFERROR($F7*$M7,"") | O7: AW:Tested in POC with success | Q7: 3 | U7: 3 | V7: 3 | W7: =IFERROR(AVERAGE(Q7:V7),"") | X7: =IFERROR($F7*$W7,"") | AG7: =IFERROR(AVERAGE(AA7:AF7),"") | AH7: =IFERROR($F7*AG7,"")
B8: T. 05 | C8: RHEL 8.2 backup / restore | D8: Backup and restore success | E8: Functional | F8: 1 | G8: 3 | K8: 3 | L8: 3 | M8: =IFERROR(AVERAGE($G8,$H8,$I8,$J8,$K8,$L8),"") | N8: =IFERROR($F8*$M8,"") | O8: AW:Tested in POC with success | Q8: 3 | U8: 3 | V8: 3 | W8: =IFERROR(AVERAGE(Q8:V8),"") | X8: =IFERROR($F8*$W8,"") | AG8: =IFERROR(AVERAGE(AA8:AF8),"") | AH8: =IFERROR($F8*AG8,"")
B9: T. 06 | C9: SLES 12 backup / restore | D9: Backup and restore success | E9: Functional | F9: 1 | G9: 3 | K9: 3 | L9: 3 | M9: =IFERROR(AVERAGE($G9,$H9,$I9,$J9,$K9,$L9),"") | N9: =IFERROR($F9*$M9,"") | O9: AW:Tested in POC with success | Q9: 3 | U9: 3 | V9: 3 | W9: =IFERROR(AVERAGE(Q9:V9),"") | X9: =IFERROR($F9*$W9,"") | AG9: =IFERROR(AVERAGE(AA9:AF9),"") | AH9: =IFERROR($F9*AG9,"")
B10: T. 07 | C10: Selectively restore files | D10: Backup and restore success | E10: Functional | F10: 1 | G10: 3 | K10: 3 | L10: 3 | M10: =IFERROR(AVERAGE($G10,$H10,$I10,$J10,$K10,$L10),"") | N10: =IFERROR($F10*$M10,"") | O10: AW:Tested in POC with success | Q10: 3 | U10: 3 | V10: 3 | W10: =IFERROR(AVERAGE(Q10:V10),"") | X10: =IFERROR($F10*$W10,"") | AG10: =IFERROR(AVERAGE(AA10:AF10),"") | AH10: =IFERROR($F10*AG10,"")
B11: T. 08 | C11: DR / Cluster failover / restore | D11: Still able to backup / restore during DR / failover etc Moved to T47-T48 to reflect the corresponding weighting in the POC | E11: Functional | F11: 3 | M11: =IFERROR(AVERAGE($G11,$H11,$I11,$J11,$K11,$L11),"") | N11: =IFERROR($F11*$M11,"") | P11: Please perform the corresponding scoring in T47-T48 | W11: =IFERROR(AVERAGE(Q11:V11),"") | X11: =IFERROR($F11*$W11,"") | AG11: =IFERROR(AVERAGE(AA11:AF11),"") | AH11: =IFERROR($F11*AG11,"")
B12: T. 09 | C12: Active-Active backup between two regions | D12: Two copies of data were store in two Azure region Moved to T45-T46 to reflect the corresponding weighting in the POC | E12: Functional | F12: 3 | M12: =IFERROR(AVERAGE($G12,$H12,$I12,$J12,$K12,$L12),"") | N12: =IFERROR($F12*$M12,"") | P12: Please perform the corresponding scoring in T45-T46 | W12: =IFERROR(AVERAGE(Q12:V12),"") | X12: =IFERROR($F12*$W12,"") | AG12: =IFERROR(AVERAGE(AA12:AF12),"") | AH12: =IFERROR($F12*AG12,"")
B13: T. 10 | C13: RBAC control to separate the duties of HK / SG to manage their own VMs / reports etc. | D13: each BU can only access to their own VM added capability of assign different level of premission to differnet accounts request backend premission on the need basis | E13: Functional | F13: 3 | G13: 3 | K13: 3 | L13: 3 | M13: =IFERROR(AVERAGE($G13,$H13,$I13,$J13,$K13,$L13),"") | N13: =IFERROR($F13*$M13,"") | O13: AW:Tested in POC with success | P13: AW : Commvault is able to have differnet premission : Admin , Oper , Readonly in the management panel while the backend accounts can request minimum premission and working in our AIA envirnoment | Q13: 2 | U13: 2 | V13: 2 | W13: =IFERROR(AVERAGE(Q13:V13),"") | X13: =IFERROR($F13*$W13,"") | Y13: AW:Veeam can provide differnent access - Admin or Read only on the interfiace , the backend AAD app acount requires contributor and Global administrator to work | AG13: =IFERROR(AVERAGE(AA13:AF13),"") | AH13: =IFERROR($F13*AG13,"")
B14: T. 11 | C14: MS SQL server 2016/2019 | D14: Backup and restore DB , partial data restored | E14: Functional | F14: 2 | G14: 3 | K14: 3 | L14: 3 | M14: =IFERROR(AVERAGE($G14,$H14,$I14,$J14,$K14,$L14),"") | N14: =IFERROR($F14*$M14,"") | O14: AW:Tested in POC with success | Q14: 3 | U14: 3 | V14: 3 | W14: =IFERROR(AVERAGE(Q14:V14),"") | X14: =IFERROR($F14*$W14,"") | AG14: =IFERROR(AVERAGE(AA14:AF14),"") | AH14: =IFERROR($F14*AG14,"")
B15: T. 12 | C15: MS SQL Managed instance | D15: Backup and restore DB , partial data restored | E15: Functional | F15: 2 | M15: =IFERROR(AVERAGE($G15,$H15,$I15,$J15,$K15,$L15),"") | N15: =IFERROR($F15*$M15,"") | W15: =IFERROR(AVERAGE(Q15:V15),"") | X15: =IFERROR($F15*$W15,"") | AG15: =IFERROR(AVERAGE(AA15:AF15),"") | AH15: =IFERROR($F15*AG15,"")
B16: T. 13 | C16: Oracle | D16: Backup and restore DB , partial data restored | E16: Functional | F16: 2 | M16: =IFERROR(AVERAGE($G16,$H16,$I16,$J16,$K16,$L16),"") | N16: =IFERROR($F16*$M16,"") | W16: =IFERROR(AVERAGE(Q16:V16),"") | X16: =IFERROR($F16*$W16,"") | AG16: =IFERROR(AVERAGE(AA16:AF16),"") | AH16: =IFERROR($F16*AG16,"")
B17: T. 14 | C17: Data Deduplication | D17: Actual storage consumption reduced | E17: Non-Functional | F17: 3 | G17: 3 | K17: 3 | L17: 3 | M17: =IFERROR(AVERAGE($G17,$H17,$I17,$J17,$K17,$L17),"") | N17: =IFERROR($F17*$M17,"") | O17: AW:92.6% is able to meet AIA requriement of 85% | P17: AW:give them a "3" first | Q17: 2 | U17: 2 | V17: 2 | W17: =IFERROR(AVERAGE(Q17:V17),"") | X17: =IFERROR($F17*$W17,"") | Y17: AW: The deduplication result is not available on system but use excel for manual calculation on POC only | AG17: =IFERROR(AVERAGE(AA17:AF17),"") | AH17: =IFERROR($F17*AG17,"")
B18: T. 15 | C18: Compression Ratio | D18: Data being compressed - will compare based on report figure | E18: Non-Functional | F18: 3 | M18: =IFERROR(AVERAGE($G18,$H18,$I18,$J18,$K18,$L18),"") | N18: =IFERROR($F18*$M18,"") | W18: =IFERROR(AVERAGE(Q18:V18),"") | X18: =IFERROR($F18*$W18,"") | AG18: =IFERROR(AVERAGE(AA18:AF18),"") | AH18: =IFERROR($F18*AG18,"")
B19: T. 16 | C19: Infrastructure Complexity | D19: The complexity to setup and to manage , installation , setup complexity | E19: Non-Functional | F19: 3 | G19: 3 | K19: 3 | L19: 3 | M19: =IFERROR(AVERAGE($G19,$H19,$I19,$J19,$K19,$L19),"") | N19: =IFERROR($F19*$M19,"") | O19: AW:As soon as the requirements are ready ( AAD account ) , the basic setup is pretty quick (within 45 mintues) AW:Comvault is able to provide precise security requirement for account creation and it works when the account is ready AW:The integration with OKTA is smooth AW:Architecture of Commvault is simple and scalble as only need to deploy Media Agent (Backup proxy) on N+1 configuration | P19: AW:give them a "3" because it is smooth to implment in AIA | Q19: 1 | R19: 3 | U19: 3 | V19: 2 | W19: =IFERROR(AVERAGE(Q19:V19),"") | X19: =IFERROR($F19*$W19,"") | Y19: AW:There are some components not able to setup as it requires Global Administrator to work | AG19: =IFERROR(AVERAGE(AA19:AF19),"") | AH19: =IFERROR($F19*AG19,"")
B20: T. 17 | C20: Reporting functions & features | D20: Backup report , policy report , storage report etc. | E20: Functional | F20: 3 | G20: 2 | K20: 2 | L20: 1 | M20: =IFERROR(AVERAGE($G20,$H20,$I20,$J20,$K20,$L20),"") | N20: =IFERROR($F20*$M20,"") | O20: AW:Out of the box the product is able to provide backup report , policy report etc. ZS: Commvault features are not as user friendly as it can't be viewed in a single Dashboard view | P20: AW:Give them a "2" at the moment until can compare with Veeam which will give "3" to the best vendor | Q20: 1 | U20: 2 | V20: 2 | W20: =IFERROR(AVERAGE(Q20:V20),"") | X20: =IFERROR($F20*$W20,"") | Y20: AW:Veeam has a differnet architecture than Commvault and there are some components not able to setup as it requires global Administrator to work and e.g. the deduplication report needs to calculate manually by excel But based on what I am seeing on the demo , the reporting features are rich in Veeam but this score is based on what is perform on the POC ZS:Veeam user interface has a consolidated view and much better to navigate but sadly their reporting features is partially available in their current Veeam Backup for Azure as most reporting features are available in their Veeam Backup & Replication. | AG20: =IFERROR(AVERAGE(AA20:AF20),"") | AH20: =IFERROR($F20*AG20,"")
B21: T. 18 | C21: backup/restore of PaaS services (e.g. Azure SQL, AKS…) | D21: Able to backup / Restore Azure SQL / AKS , function check only | E21: Functional | F21: 2 | M21: =IFERROR(AVERAGE($G21,$H21,$I21,$J21,$K21,$L21),"") | N21: =IFERROR($F21*$M21,"") | W21: =IFERROR(AVERAGE(Q21:V21),"") | X21: =IFERROR($F21*$W21,"") | AG21: =IFERROR(AVERAGE(AA21:AF21),"") | AH21: =IFERROR($F21*AG21,"")
B22: T. 19 | C22: Infrastructure sizing - concurrent backup / restore | D22: Multiple backup are able to conduct in parallel in a scalable architecture | E22: Functional | F22: 2 | G22: 3 | K22: 3 | L22: 1 | M22: =IFERROR(AVERAGE($G22,$H22,$I22,$J22,$K22,$L22),"") | N22: =IFERROR($F22*$M22,"") | O22: AW:Comvault's architecture overall is simple and scalable, however it is difficult to measure with other vendor's solution as the architecture is different ZS:Commvault backup is still based on traditional backup technology and not able to auto scale based on workload as concurrent backups will be placed in the backup queue | P22: AW:Give them a "3" because it is "easiest to implment in AIA" | Q22: 3 | U22: 3 | V22: 3 | W22: =IFERROR(AVERAGE(Q22:V22),"") | X22: =IFERROR($F22*$W22,"") | Y22: ZS:Veeam is able to spin up new instances to cater for concurrent backup workloads easily | AG22: =IFERROR(AVERAGE(AA22:AF22),"") | AH22: =IFERROR($F22*AG22,"")
B23: T. 20 | C23: Storage tiering (Different policy store to different tier of e.g. Azure hot/cold blob) | D23: Different policy for differnet retention supported | E23: Functional | F23: 3 | G23: 3 | K23: 3 | L23: 3 | M23: =IFERROR(AVERAGE($G23,$H23,$I23,$J23,$K23,$L23),"") | N23: =IFERROR($F23*$M23,"") | O23: AW:All AIA requirements are supported and able to capture in AIA envirnoment | Q23: 3 | U23: 3 | V23: 3 | W23: =IFERROR(AVERAGE(Q23:V23),"") | X23: =IFERROR($F23*$W23,"") | AG23: =IFERROR(AVERAGE(AA23:AF23),"") | AH23: =IFERROR($F23*AG23,"")
B24: T. 21 | C24: Archive tier support | D24: Azure Archive Blob support | E24: Functional | F24: 3 | G24: 3 | K24: 3 | L24: 3 | M24: =IFERROR(AVERAGE($G24,$H24,$I24,$J24,$K24,$L24),"") | N24: =IFERROR($F24*$M24,"") | O24: AW:Support but not test in AIA enivonrment due to envnrionment contraint | Q24: 3 | U24: 3 | V24: 3 | W24: =IFERROR(AVERAGE(Q24:V24),"") | X24: =IFERROR($F24*$W24,"") | AG24: =IFERROR(AVERAGE(AA24:AF24),"") | AH24: =IFERROR($F24*AG24,"")
B25: T. 22 | C25: Pricing structure | D25: single and simple charging mechanism | E25: Functional | F25: 3 | M25: =IFERROR(AVERAGE($G25,$H25,$I25,$J25,$K25,$L25),"") | N25: =IFERROR($F25*$M25,"") | W25: =IFERROR(AVERAGE(Q25:V25),"") | X25: =IFERROR($F25*$W25,"") | AG25: =IFERROR(AVERAGE(AA25:AF25),"") | AH25: =IFERROR($F25*AG25,"")
B26: T. 23 | C26: Auto Tiering support | D26: Move Monthly backup from Cold / Hot to Azure tier automatically | E26: Functional | F26: 3 | G26: 3 | K26: 3 | L26: 3 | M26: =IFERROR(AVERAGE($G26,$H26,$I26,$J26,$K26,$L26),"") | N26: =IFERROR($F26*$M26,"") | O26: AW:Support but not test in AIA enivonrment due to envnrionment contraint | Q26: 3 | U26: 3 | V26: 3 | W26: =IFERROR(AVERAGE(Q26:V26),"") | X26: =IFERROR($F26*$W26,"") | AG26: =IFERROR(AVERAGE(AA26:AF26),"") | AH26: =IFERROR($F26*AG26,"")
B27: T. 24 | C27: Data at rest encryption | D27: Backup encrypted | E27: Functional | F27: 1 | G27: 3 | K27: 3 | L27: 3 | M27: =IFERROR(AVERAGE($G27,$H27,$I27,$J27,$K27,$L27),"") | N27: =IFERROR($F27*$M27,"") | O27: AW:Support but not test in AIA enivonrment due to envnrionment contraint | Q27: 3 | U27: 3 | V27: 3 | W27: =IFERROR(AVERAGE(Q27:V27),"") | X27: =IFERROR($F27*$W27,"") | AG27: =IFERROR(AVERAGE(AA27:AF27),"") | AH27: =IFERROR($F27*AG27,"")
B28: T. 25 | C28: Azure Keyvault integration | D28: Encryption Key intgration with Azure Keyvault | E28: Functional | F28: 2 | G28: 3 | K28: 3 | L28: 3 | M28: =IFERROR(AVERAGE($G28,$H28,$I28,$J28,$K28,$L28),"") | N28: =IFERROR($F28*$M28,"") | O28: AW:Support but not test in AIA enivonrment due to envnrionment contraint | Q28: 3 | U28: 3 | V28: 3 | W28: =IFERROR(AVERAGE(Q28:V28),"") | X28: =IFERROR($F28*$W28,"") | Y28: AW:Support but not test in AIA enivonrment due to envnrionment contraint | AG28: =IFERROR(AVERAGE(AA28:AF28),"") | AH28: =IFERROR($F28*AG28,"")
B29: T. 26 | C29: Two Copies of backup to two Azure Region | D29: Two copies of data , one in Azure EA and another in Azure SEA | E29: Functional | F29: 1 | G29: 3 | K29: 3 | L29: 3 | M29: =IFERROR(AVERAGE($G29,$H29,$I29,$J29,$K29,$L29),"") | N29: =IFERROR($F29*$M29,"") | O29: AW:Tested in POC with success | Q29: 1 | R29: 2 | U29: 1 | V29: 2 | W29: =IFERROR(AVERAGE(Q29:V29),"") | X29: =IFERROR($F29*$W29,"") | Y29: AW: Veeam is able to provide demo in their own environment as this test is not able to perform in AIA POC environment due to setup contraint in AIA : Require Global Administrator to work | AG29: =IFERROR(AVERAGE(AA29:AF29),"") | AH29: =IFERROR($F29*AG29,"")
B30: T. 27 | C30: Network replication efficiency (send compressed / deduplicated backup only) | D30: Demonostrate only the "delta" are replicated | E30: Functional | F30: 2 | G30: 3 | K30: 3 | L30: 3 | M30: =IFERROR(AVERAGE($G30,$H30,$I30,$J30,$K30,$L30),"") | N30: =IFERROR($F30*$M30,"") | O30: AW:Tested in POC with success | Q30: 2 | U30: 2 | V30: 2 | W30: =IFERROR(AVERAGE(Q30:V30),"") | X30: =IFERROR($F30*$W30,"") | Y30: AW:Not available to see in AIA enivonrment about the efficiency as Veeam Replication is not able to run in POC | AG30: =IFERROR(AVERAGE(AA30:AF30),"") | AH30: =IFERROR($F30*AG30,"")
B31: T. 28 | C31: Restore backup to new VM | D31: Able to restore backup as new VM | E31: Functional | F31: 2 | G31: 3 | K31: 3 | L31: 3 | M31: =IFERROR(AVERAGE($G31,$H31,$I31,$J31,$K31,$L31),"") | N31: =IFERROR($F31*$M31,"") | O31: AW:Tested in POC with success | Q31: 3 | U31: 3 | V31: 3 | W31: =IFERROR(AVERAGE(Q31:V31),"") | X31: =IFERROR($F31*$W31,"") | AG31: =IFERROR(AVERAGE(AA31:AF31),"") | AH31: =IFERROR($F31*AG31,"")
B32: T. 29 | C32: Backup store in another cloud provider | D32: Support data replication to another cloud provider - AWS - GCP | E32: Optional | F32: 1 | M32: =IFERROR(AVERAGE($G32,$H32,$I32,$J32,$K32,$L32),"") | N32: =IFERROR($F32*$M32,"") | W32: =IFERROR(AVERAGE(Q32:V32),"") | X32: =IFERROR($F32*$W32,"") | AG32: =IFERROR(AVERAGE(AA32:AF32),"") | AH32: =IFERROR($F32*AG32,"")
B33: T. 30 | C33: Restore backup to another cloud provider | D33: Capability to orchestrate restoration to another cloud provider - AWS - GCP | E33: Optional | F33: 1 | M33: =IFERROR(AVERAGE($G33,$H33,$I33,$J33,$K33,$L33),"") | N33: =IFERROR($F33*$M33,"") | W33: =IFERROR(AVERAGE(Q33:V33),"") | X33: =IFERROR($F33*$W33,"") | AG33: =IFERROR(AVERAGE(AA33:AF33),"") | AH33: =IFERROR($F33*AG33,"")
B34: T. 31 | C34: AS/400 support | D34: if there is a chance to support AS/400 without building new set of infrastructure - extension of existing infra etc. | E34: Optional | F34: 1 | M34: =IFERROR(AVERAGE($G34,$H34,$I34,$J34,$K34,$L34),"") | N34: =IFERROR($F34*$M34,"") | W34: =IFERROR(AVERAGE(Q34:V34),"") | X34: =IFERROR($F34*$W34,"") | AG34: =IFERROR(AVERAGE(AA34:AF34),"") | AH34: =IFERROR($F34*AG34,"")
B35: T. 32 | C35: Retention Period | D35: Able to backup back on AIA defined policty | E35: Non-Functional | F35: 1 | G35: 3 | K35: 3 | L35: 3 | M35: =IFERROR(AVERAGE($G35,$H35,$I35,$J35,$K35,$L35),"") | N35: =IFERROR($F35*$M35,"") | O35: AW:Tested in POC with success | Q35: 3 | U35: 3 | V35: 3 | W35: =IFERROR(AVERAGE(Q35:V35),"") | X35: =IFERROR($F35*$W35,"") | AG35: =IFERROR(AVERAGE(AA35:AF35),"") | AH35: =IFERROR($F35*AG35,"")
B36: T. 33 | C36: Data Volume (1000 VM) | D36: 100GB per OS backup (usable) | E36: Non-Functional | F36: 3 | M36: =IFERROR(AVERAGE($G36,$H36,$I36,$J36,$K36,$L36),"") | N36: =IFERROR($F36*$M36,"") | W36: =IFERROR(AVERAGE(Q36:V36),"") | X36: =IFERROR($F36*$W36,"") | AG36: =IFERROR(AVERAGE(AA36:AF36),"") | AH36: =IFERROR($F36*AG36,"")
B37: T. 34 | C37: Backup/restore frequency | D37: 42 daily , 13 monthly , 8 yearly | E37: Non-Functional | F37: 1 | G37: 3 | K37: 3 | L37: 3 | M37: =IFERROR(AVERAGE($G37,$H37,$I37,$J37,$K37,$L37),"") | N37: =IFERROR($F37*$M37,"") | O37: AW:Tested in POC with success | Q37: 3 | U37: 3 | V37: 3 | W37: =IFERROR(AVERAGE(Q37:V37),"") | X37: =IFERROR($F37*$W37,"") | AG37: =IFERROR(AVERAGE(AA37:AF37),"") | AH37: =IFERROR($F37*AG37,"")
B38: T. 35 | C38: Restore time | D38: Compare among three vendors for same set of POC machines | E38: Non-Functional | F38: 3 | G38: 3 | K38: 3 | L38: 3 | M38: =IFERROR(AVERAGE($G38,$H38,$I38,$J38,$K38,$L38),"") | N38: =IFERROR($F38*$M38,"") | O38: AW:Backup time based on around 2.93 TB of 9 VMs Nov 5 :job id 164676 is 2 hours 38 min 37 seconds Nov 7 - 12 are having similar size and time Restore job (Restore as new) - 34.67GB of data for SGAZEULAP0029 Oct 28:Job ID 149564 is 23 min 18 seconds | P38: AW: It is hard to give comparision between the vendors but will give a "3" for the fastest vendor and "2" for the second vendor | Q38: 2 | U38: 2 | V38: 3 | W38: =IFERROR(AVERAGE(Q38:V38),"") | X38: =IFERROR($F38*$W38,"") | Y38: AW: there is not enough time to test 9 VM backup together before the closing of POC , there is no apple to apple comparision with commvault | AG38: =IFERROR(AVERAGE(AA38:AF38),"") | AH38: =IFERROR($F38*AG38,"")
B39: T. 36 | C39: Ease of Deployment | D39: Comparison between three vendors | E39: Non-Functional | F39: 1 | G39: 3 | K39: 2 | L39: 2 | M39: =IFERROR(AVERAGE($G39,$H39,$I39,$J39,$K39,$L39),"") | N39: =IFERROR($F39*$M39,"") | O39: AW:Commvault setup is easiest among the two vendors that are runing in AIA as they can start the backup test as soon as the corresponding premission were given ZS:Commvault need to perform certain tasks for example providing User Access Control which is done in the frontend but need to be configured in their backend | P39: AW: give them a "3" for this reason another vendor will give a "2" or "1" correspondingly | Q39: 2 | R39: 2 | U39: 2 | V39: 3 | W39: =IFERROR(AVERAGE(Q39:V39),"") | X39: =IFERROR($F39*$W39,"") | Y39: AW:Veeam has a differnet architecture and there are some components not able to setup as it requires global Administrator to work. A full setup will reuqire even more component to be deploy ZS:Veeam has a better scalable architecture. However, some features thats available thru Veeam Backup Replication need to be made available in Veeam Backup for Azure especially on the reporting feature | AG39: =IFERROR(AVERAGE(AA39:AF39),"") | AH39: =IFERROR($F39*AG39,"")
B40: T. 37 | C40: Agentless Backup for OS on Cloud | D40: Ability to backup OS's without the need of an Agent | E40: Functional | F40: 3 | M40: =IFERROR(AVERAGE($G40,$H40,$I40,$J40,$K40,$L40),"") | N40: =IFERROR($F40*$M40,"") | W40: =IFERROR(AVERAGE(Q40:V40),"") | X40: =IFERROR($F40*$W40,"") | AG40: =IFERROR(AVERAGE(AA40:AF40),"") | AH40: =IFERROR($F40*AG40,"")
B41: T. 38 | C41: Support SAML or any identity provider. | D41: To enumerate and use Okta identity to provide RBAC. | E41: Functional | F41: 3 | M41: =IFERROR(AVERAGE($G41,$H41,$I41,$J41,$K41,$L41),"") | N41: =IFERROR($F41*$M41,"") | W41: =IFERROR(AVERAGE(Q41:V41),"") | X41: =IFERROR($F41*$W41,"") | AG41: =IFERROR(AVERAGE(AA41:AF41),"") | AH41: =IFERROR($F41*AG41,"")
...

Sheet Inputs
B3: Category | E3: Weightage | G3: Capability [& Maturity] | J3: Type | L3: Compliance
B5: Access Controls | E5: 1 | G5: 0 | J5: Functional | L5: In-Full
B6: Architecture | E6: 2 | G6: 1 | J6: Non-Functional | L6: Partially
B7: Automation | E7: 3 | G7: 2 | J7: Optional | L7: Non-Compliant
B8: Billing Model | G8: 3 | L8: Planned
B9: Cloud Readiness
B10: Cost & Contract
B11: Delivery & Transition
B12: Functional Capabilities
B13: High Availability
B14: Innovation
B15: Integration
B16: Log, Monitor & Alerts
B17: Support Model
B18: Open Standards
B19: Operations
B20: Performance
... B26: User Experience
